<?xml version="1.0" encoding="utf-8"?>
<!-- =================================================================================== -->
<!-- |    This document was autogenerated by xacro from hyq.urdf.xacro                 | -->
<!-- |    EDITING THIS FILE BY HAND IS NOT RECOMMENDED                                 | -->
<!-- =================================================================================== -->
<robot name="hyq">
  <!-- Floating-base Joint -->
  <joint name="floating_base" type="fixed">
    <origin rpy="0 0 0" xyz="0 0 0"/>
    <parent link="base"/>
    <child link="trunk"/>
  </joint>
  <!-- Footprint link -->
  <link name="base">
    <visual>
      <geometry>
        <cylinder length="0.01" radius="0.01"/>
      </geometry>
    </visual>
  </link>
  <!-- Trunk link -->
  <link name="trunk">
    <visual>
      <geometry>
        <mesh filename="package://xpp_hyq/meshes/trunk/trunk.dae" scale="1 1 1"/>
      </geometry>
    </visual>
    <collision>
      <geometry>
        <mesh filename="package://xpp_hyq/meshes/trunk/trunk.dae" scale="1 1 1"/>
      </geometry>
    </collision>
  </link>
  <!-- Joints -->
  <!-- Hip assembly joint -->
  <joint name="lf_haa_joint" type="revolute">
    <origin rpy="0 1.57079632679 3.14159265359" xyz="0.3735 0.207 0"/>
    <parent link="trunk"/>
    <child link="lf_hipassembly"/>
    <axis xyz="0 0 1"/>
    <limit effort="150.0" lower="-1.2217304764" upper="0.523598775598" velocity="12.0"/>
  </joint>
  <!-- Upper leg joint -->
  <joint name="lf_hfe_joint" type="revolute">
    <origin rpy="1.57079632679 0 0" xyz="0.082 0 0"/>
    <parent link="lf_hipassembly"/>
    <child link="lf_upperleg"/>
    <axis xyz="0 0 1"/>
    <limit effort="150.0" lower="-0.872664625997" upper="1.2217304764" velocity="12.0"/>
  </joint>
  <!-- Lower leg joint -->
  <joint name="lf_kfe_joint" type="revolute">
    <origin rpy="0 0 0" xyz="0.35 0 0"/>
    <parent link="lf_upperleg"/>
    <child link="lf_lowerleg"/>
    <axis xyz="0 0 1"/>
    <limit effort="150.0" lower="-2.44346095279" upper="-0.349065850399" velocity="12.0"/>
  </joint>
  <!-- Foot joint -->
  <joint name="lf_foot_joint" type="fixed">
    <origin rpy="1.57079632679 0 -1.57079632679" xyz="0.35 0 0"/>
    <parent link="lf_lowerleg"/>
    <child link="lf_foot"/>
  </joint>
  <!-- Links -->
  <!-- Hip assembly link -->
  <link name="lf_hipassembly">
    <visual>
      <origin rpy="0.0 0 0" xyz="0 0 0"/>
      <geometry>
        <mesh filename="package://xpp_hyq/meshes/leg/hipassembly.dae" scale="1 1 1"/>
      </geometry>
    </visual>
  </link>
  <!-- Upper leg link -->
  <link name="lf_upperleg">
    <visual>
      <origin rpy="0.0 0 0" xyz="0 0 0"/>
      <geometry>
        <mesh filename="package://xpp_hyq/meshes/leg/upperleg.dae" scale="1 1 1"/>
      </geometry>
    </visual>
  </link>
  <!-- Lower leg link -->
  <link name="lf_lowerleg">
    <visual>
      <geometry>
        <mesh filename="package://xpp_hyq/meshes/leg/lowerleg.dae" scale="1 1 1"/>
      </geometry>
      <material name="white"/>
    </visual>
  </link>
  <!-- Foot link -->
  <link name="lf_foot">
    <!--<visual>
				<origin xyz="0.0 0.0 0.0" rpy="0.0 0.0 0.0"/>
				<geometry>
					<sphere radius="0.021"/>
				</geometry>
			</visual>-->
  </link>
  <!-- Joints -->
  <!-- Hip assembly joint -->
  <joint name="rf_haa_joint" type="revolute">
    <origin rpy="0 1.57079632679 0" xyz="0.3735 -0.207 0"/>
    <parent link="trunk"/>
    <child link="rf_hipassembly"/>
    <axis xyz="0 0 1"/>
    <limit effort="150.0" lower="-1.2217304764" upper="0.523598775598" velocity="12.0"/>
  </joint>
  <!-- Upper leg joint -->
  <joint name="rf_hfe_joint" type="revolute">
    <origin rpy="-1.57079632679 0 0" xyz="0.082 0 0"/>
    <parent link="rf_hipassembly"/>
    <child link="rf_upperleg"/>
    <axis xyz="0 0 1"/>
    <limit effort="150.0" lower="-0.872664625997" upper="1.2217304764" velocity="12.0"/>
  </joint>
  <!-- Lower leg joint -->
  <joint name="rf_kfe_joint" type="revolute">
    <origin rpy="0 0 0" xyz="0.35 0 0"/>
    <parent link="rf_upperleg"/>
    <child link="rf_lowerleg"/>
    <axis xyz="0 0 1"/>
    <limit effort="150.0" lower="-2.44346095279" upper="-0.349065850399" velocity="12.0"/>
  </joint>
  <!-- Foot joint -->
  <joint name="rf_foot_joint" type="fixed">
    <origin rpy="1.57079632679 0 -1.57079632679" xyz="0.35 0 0"/>
    <parent link="rf_lowerleg"/>
    <child link="rf_foot"/>
  </joint>
  <!-- Links -->
  <!-- Hip assembly link -->
  <link name="rf_hipassembly">
    <visual>
      <origin rpy="3.14159265359 0 0" xyz="0 0 0"/>
      <geometry>
        <mesh filename="package://xpp_hyq/meshes/leg/hipassembly.dae" scale="1 1 1"/>
      </geometry>
    </visual>
  </link>
  <!-- Upper leg link -->
  <link name="rf_upperleg">
    <visual>
      <origin rpy="0.0 0 0" xyz="0 0 0"/>
      <geometry>
        <mesh filename="package://xpp_hyq/meshes/leg/upperleg.dae" scale="1 1 1"/>
      </geometry>
    </visual>
  </link>
  <!-- Lower leg link -->
  <link name="rf_lowerleg">
    <visual>
      <geometry>
        <mesh filename="package://xpp_hyq/meshes/leg/lowerleg.dae" scale="1 1 1"/>
      </geometry>
      <material name="white"/>
    </visual>
  </link>
  <!-- Foot link -->
  <link name="rf_foot">
    <!--<visual>
				<origin xyz="0.0 0.0 0.0" rpy="0.0 0.0 0.0"/>
				<geometry>
					<sphere radius="0.021"/>
				</geometry>
			</visual>-->
  </link>
  <!-- Joints -->
  <!-- Hip assembly joint -->
  <joint name="lh_haa_joint" type="revolute">
    <origin rpy="0 1.57079632679 3.14159265359" xyz="-0.3735 0.207 0"/>
    <parent link="trunk"/>
    <child link="lh_hipassembly"/>
    <axis xyz="0 0 1"/>
    <limit effort="150.0" lower="-1.2217304764" upper="0.523598775598" velocity="12.0"/>
  </joint>
  <!-- Upper leg joint -->
  <joint name="lh_hfe_joint" type="revolute">
    <origin rpy="1.57079632679 0 0" xyz="0.082 0 0"/>
    <parent link="lh_hipassembly"/>
    <child link="lh_upperleg"/>
    <axis xyz="0 0 1"/>
    <limit effort="150.0" lower="-1.2217304764" upper="0.872664625997" velocity="12.0"/>
  </joint>
  <!-- Lower leg joint -->
  <joint name="lh_kfe_joint" type="revolute">
    <origin rpy="0 0 0" xyz="0.35 0 0"/>
    <parent link="lh_upperleg"/>
    <child link="lh_lowerleg"/>
    <axis xyz="0 0 1"/>
    <limit effort="150.0" lower="0.349065850399" upper="2.44346095279" velocity="12.0"/>
  </joint>
  <!-- Foot joint -->
  <joint name="lh_foot_joint" type="fixed">
    <origin rpy="1.57079632679 0 -1.57079632679" xyz="0.35 0 0"/>
    <parent link="lh_lowerleg"/>
    <child link="lh_foot"/>
  </joint>
  <!-- Links -->
  <!-- Hip assembly link -->
  <link name="lh_hipassembly">
    <visual>
      <origin rpy="3.14159265359 0 0" xyz="0 0 0"/>
      <geometry>
        <mesh filename="package://xpp_hyq/meshes/leg/hipassembly.dae" scale="1 1 1"/>
      </geometry>
    </visual>
  </link>
  <!-- Upper leg link -->
  <link name="lh_upperleg">
    <visual>
      <origin rpy="3.14159265359 0 0" xyz="0 0 0"/>
      <geometry>
        <mesh filename="package://xpp_hyq/meshes/leg/upperleg.dae" scale="1 1 1"/>
      </geometry>
    </visual>
  </link>
  <!-- Lower leg link -->
  <link name="lh_lowerleg">
    <visual>
      <geometry>
        <mesh filename="package://xpp_hyq/meshes/leg/lowerleg.dae" scale="1 1 1"/>
      </geometry>
      <material name="white"/>
    </visual>
  </link>
  <!-- Foot link -->
  <link name="lh_foot">
    <!--<visual>
				<origin xyz="0.0 0.0 0.0" rpy="0.0 0.0 0.0"/>
				<geometry>
					<sphere radius="0.021"/>
				</geometry>
			</visual>-->
  </link>
  <!-- Joints -->
  <!-- Hip assembly joint -->
  <joint name="rh_haa_joint" type="revolute">
    <origin rpy="0 1.57079632679 0" xyz="-0.3735 -0.207 0"/>
    <parent link="trunk"/>
    <child link="rh_hipassembly"/>
    <axis xyz="0 0 1"/>
    <limit effort="150.0" lower="-1.2217304764" upper="0.523598775598" velocity="12.0"/>
  </joint>
  <!-- Upper leg joint -->
  <joint name="rh_hfe_joint" type="revolute">
    <origin rpy="-1.57079632679 0 0" xyz="0.082 0 0"/>
    <parent link="rh_hipassembly"/>
    <child link="rh_upperleg"/>
    <axis xyz="0 0 1"/>
    <limit effort="150.0" lower="-1.2217304764" upper="0.872664625997" velocity="12.0"/>
  </joint>
  <!-- Lower leg joint -->
  <joint name="rh_kfe_joint" type="revolute">
    <origin rpy="0 0 0" xyz="0.35 0 0"/>
    <parent link="rh_upperleg"/>
    <child link="rh_lowerleg"/>
    <axis xyz="0 0 1"/>
    <limit effort="150.0" lower="0.349065850399" upper="2.44346095279" velocity="12.0"/>
  </joint>
  <!-- Foot joint -->
  <joint name="rh_foot_joint" type="fixed">
    <origin rpy="1.57079632679 0 -1.57079632679" xyz="0.35 0 0"/>
    <parent link="rh_lowerleg"/>
    <child link="rh_foot"/>
  </joint>
  <!-- Links -->
  <!-- Hip assembly link -->
  <link name="rh_hipassembly">
    <visual>
      <origin rpy="0.0 0 0" xyz="0 0 0"/>
      <geometry>
        <mesh filename="package://xpp_hyq/meshes/leg/hipassembly.dae" scale="1 1 1"/>
      </geometry>
    </visual>
  </link>
  <!-- Upper leg link -->
  <link name="rh_upperleg">
    <visual>
      <origin rpy="3.14159265359 0 0" xyz="0 0 0"/>
      <geometry>
        <mesh filename="package://xpp_hyq/meshes/leg/upperleg.dae" scale="1 1 1"/>
      </geometry>
    </visual>
  </link>
  <!-- Lower leg link -->
  <link name="rh_lowerleg">
    <visual>
      <geometry>
        <mesh filename="package://xpp_hyq/meshes/leg/lowerleg.dae" scale="1 1 1"/>
      </geometry>
      <material name="white"/>
    </visual>
  </link>
  <!-- Foot link -->
  <link name="rh_foot">
    <!--<visual>
				<origin xyz="0.0 0.0 0.0" rpy="0.0 0.0 0.0"/>
				<geometry>
					<sphere radius="0.021"/>
				</geometry>
			</visual>-->
  </link>
</robot>

